<?xml version="1.0" ?>
<!-- =================================================================================== -->
<!-- |    This document was autogenerated by xacro from /home/fandes/workspace/kuavo-ros-control/src/humanoid-control/humanoid_interface_drake/models/biped_gen4.0/urdf/biped_v3_arm.xacro | -->
<!-- |    EDITING THIS FILE BY HAND IS NOT RECOMMENDED                                 | -->
<!-- =================================================================================== -->
<robot name="biped_v3_arm" xmlns:drake="https://drake.mit.edu">
  <link name="torso">
    <inertial>
      <origin xyz="-0.006 0.0 0.145" rpy="0 0 0" />
      <mass value="8.730" />
      <inertia ixx="0.104" ixy="0.0" ixz="0.0" iyy="0.084" iyz="0.0" izz="0.050" />
    </inertial>
    <visual>
      <origin xyz="0 0 0" rpy="0 0 0" />
      <geometry>
        <mesh filename="../../meshes/torso.STL" />
      </geometry>
      <material name="">
        <color rgba="1 1 1 1" />
      </material>
    </visual>
  </link>
  <link name="waist">
    <inertial>
      <origin xyz="0.001 0.0 -0.122" rpy="0 0 0" />
      <mass value="4.853" />
      <inertia ixx="0.023" ixy="0.0" ixz="0.0" iyy="0.015" iyz="0.0" izz="0.017" />
    </inertial>
    <visual>
      <origin xyz="0 0 0" rpy="0 0 0" />
      <geometry>
        <mesh filename="../../meshes/waist.STL" />
      </geometry>
      <material name="">
        <color rgba="1 1 1 1" />
      </material>
    </visual>
  </link>
  <joint name="waist" type="fixed">
    <origin xyz="0 0 0" rpy="0 0 0" />
    <parent link="torso" />
    <child link="waist" />
    <axis xyz="0 0 1" />
    <limit lower="-2.0943951023932" upper="2.0943951023932" effort="36.0" velocity="23.0266666666667" />
    <dynamics damping="0.2" friction="0.0" />
  </joint>
  <!-- =========================================================== Arms ================================================================= -->
  <link name="zarm_l1_link">
    <inertial>
      <origin xyz="0.01852427 -0.00307832 -0.00006089" rpy="0 0 0" />
      <mass value="0.80328906" />
      <inertia ixx="0.00065573" ixy="-0.00004427" ixz="-0.00000010" iyy="0.00082825" iyz="-0.00000114" izz="0.00093564" />
    </inertial>
    <visual>
      <origin xyz="0 0 0" rpy="0 0 0" />
      <geometry>
        <mesh filename="../../meshes/l_arm_pitch.STL" />
      </geometry>
      <material name="">
        <color rgba="1 1 1 1" />
      </material>
    </visual>
  </link>
  <joint name="zarm_l1_joint" type="revolute">
    <origin xyz="0.0 0.18100293 0.23992606" rpy="0 0 0" />
    <parent link="torso" />
    <child link="zarm_l1_link" />
    <axis xyz="0 1 0" />
    <limit lower="-3.14159265358979" upper="2.0943951023932" effort="14.1" velocity="10.5" />
    <dynamics damping="0.2" friction="0.0" />
  </joint>
  <transmission type="SimpleTransmission">
    <joint name="zarm_l1_joint" />
    <actuator name="zarm_l1_joint_motor" />
  </transmission>
  <link name="zarm_l2_link">
    <inertial>
      <origin xyz="0.00217668 0.00574680 -0.03258678" rpy="0 0 0" />
      <mass value="0.32360735" />
      <inertia ixx="0.00046909" ixy="0.0" ixz="-0.00002559" iyy="0.00068110" iyz="0.0" izz="0.00049735" />
    </inertial>
    <visual>
      <origin xyz="0 0 0" rpy="0 0 0" />
      <geometry>
        <mesh filename="../../meshes/l_arm_roll.STL" />
      </geometry>
      <material name="">
        <color rgba="1 1 1 1" />
      </material>
    </visual>
  </link>
  <joint name="zarm_l2_joint" type="revolute">
    <origin xyz="0 0 0" rpy="0.17453 0 0" />
    <parent link="zarm_l1_link" />
    <child link="zarm_l2_link" />
    <axis xyz="1 0 0" />
    <limit lower="-0.52" upper="3.316" effort="37" velocity="15.0" />
    <dynamics damping="0.2" friction="0.0" />
  </joint>
  <transmission type="SimpleTransmission">
    <joint name="zarm_l2_joint" />
    <actuator name="zarm_l2_joint_motor" />
  </transmission>
  <link name="zarm_l3_link">
    <inertial>
      <origin xyz="-0.00006747 -0.01016408 -0.15041767" rpy="0 0 0" />
      <mass value="1.46578996" />
      <inertia ixx="0.00696550" ixy="0.00000046" ixz="0.00000200" iyy="0.00656301" iyz="-0.00085646" izz="0.00135717" />
    </inertial>
    <visual>
      <origin xyz="0 0 0" rpy="0 0 0" />
      <geometry>
        <mesh filename="../../meshes/l_arm_yaw.STL" />
      </geometry>
      <material name="">
        <color rgba="1 1 1 1" />
      </material>
    </visual>
  </link>
  <joint name="zarm_l3_joint" type="revolute">
    <origin xyz="0 0 0" rpy="0 0 0" />
    <parent link="zarm_l2_link" />
    <child link="zarm_l3_link" />
    <axis xyz="0 0 1" />
    <limit lower="-1.5707963267949" upper="1.5707963267949" effort="37" velocity="15.0" />
    <dynamics damping="0.2" friction="0.0" />
  </joint>
  <transmission type="SimpleTransmission">
    <joint name="zarm_l3_joint" />
    <actuator name="zarm_l3_joint_motor" />
  </transmission>
  <link name="zarm_l4_link">
    <inertial>
      <origin xyz="-0.00081309 -0.01331683 -0.08985563" rpy="0 0 0" />
      <mass value="0.42136972" />
      <inertia ixx="0.00335991" ixy="0.00000193" ixz="0.00001686" iyy="0.00315848" iyz="0.00008493" izz="0.00049447" />
    </inertial>
    <visual>
      <origin xyz="0 0 0" rpy="0 0 0" />
      <geometry>
        <mesh filename="../../meshes/l_forearm.STL" />
      </geometry>
      <material name="">
        <color rgba="1 1 1 1" />
      </material>
    </visual>
  </link>
  <joint name="zarm_l4_joint" type="revolute">
    <origin xyz="0 0.0 -0.20533" rpy="0 0 0" />
    <parent link="zarm_l3_link" />
    <child link="zarm_l4_link" />
    <axis xyz="0 1 0" />
    <limit lower="-2.26892802759263" upper="0.08726" effort="37" velocity="15.0" />
    <dynamics damping="0.2" friction="0.0" />
  </joint>
  <transmission type="SimpleTransmission">
    <joint name="zarm_l4_joint" />
    <actuator name="zarm_l4_joint_motor" />
  </transmission>
  <link name="zarm_l7_end_effector">
    <collision>
      <origin rpy="0 0 0" xyz="0 0 0" />
      <geometry>
        <sphere radius="0.005" />
      </geometry>
    </collision>
  </link>
  <joint name="zarm_l7_end_effector_joint" type="fixed">
    <origin xyz="0 0.0 -0.2175" rpy="0 0 0" />
    <parent link="zarm_l4_link" />
    <child link="zarm_l7_end_effector" />
  </joint>
  <link name="zarm_r1_link">
    <inertial>
      <origin xyz="0.01852427 0.00307832 -0.00006089" rpy="0 0 0" />
      <mass value="0.80328906" />
      <inertia ixx="0.00065573" ixy="0.00004427" ixz="-0.00000010" iyy="0.00082825" iyz="0.00000114" izz="0.00093564" />
    </inertial>
    <visual>
      <origin xyz="0 0 0" rpy="0 0 0" />
      <geometry>
        <mesh filename="../../meshes/r_arm_pitch.STL" />
      </geometry>
      <material name="">
        <color rgba="1 1 1 1" />
      </material>
    </visual>
  </link>
  <joint name="zarm_r1_joint" type="revolute">
    <origin xyz="0.0 -0.18100293 0.23992606" rpy="0 0 0" />
    <parent link="torso" />
    <child link="zarm_r1_link" />
    <axis xyz="0 1 0" />
    <limit lower="-3.14159265358979" upper="2.0943951023932" effort="14.1" velocity="10.5" />
    <dynamics damping="0.2" friction="0.0" />
  </joint>
  <transmission type="SimpleTransmission">
    <joint name="zarm_r1_joint" />
    <actuator name="zarm_r1_joint_motor" />
  </transmission>
  <link name="zarm_r2_link">
    <inertial>
      <origin xyz="0.00217668 -0.00574680 -0.03258678" rpy="0 0 0" />
      <mass value="0.32360735" />
      <inertia ixx="0.00046909" ixy="0.0" ixz="-0.00002559" iyy="0.00068110" iyz="0.0" izz="0.00049735" />
    </inertial>
    <visual>
      <origin xyz="0 0 0" rpy="0 0 0" />
      <geometry>
        <mesh filename="../../meshes/r_arm_roll.STL" />
      </geometry>
      <material name="">
        <color rgba="1 1 1 1" />
      </material>
    </visual>
  </link>
  <joint name="zarm_r2_joint" type="revolute">
    <origin xyz="0 0 0" rpy="-0.17453 0 0" />
    <parent link="zarm_r1_link" />
    <child link="zarm_r2_link" />
    <axis xyz="1 0 0" />
    <limit lower="-3.3161" upper="0.52" effort="37.0" velocity="15.0" />
    <dynamics damping="0.2" friction="0.0" />
  </joint>
  <transmission type="SimpleTransmission">
    <joint name="zarm_r2_joint" />
    <actuator name="zarm_r2_joint_motor" />
  </transmission>
  <link name="zarm_r3_link">
    <inertial>
      <origin xyz="-0.00006747 0.01016408 -0.15041767" rpy="0 0 0" />
      <mass value="1.46578996" />
      <inertia ixx="0.00696550" ixy="-0.00000046" ixz="0.00000200" iyy="0.00656301" iyz="0.00085646" izz="0.00135717" />
    </inertial>
    <visual>
      <origin xyz="0 0 0" rpy="0 0 0" />
      <geometry>
        <mesh filename="../../meshes/r_arm_yaw.STL" />
      </geometry>
      <material name="">
        <color rgba="1 1 1 1" />
      </material>
    </visual>
  </link>
  <joint name="zarm_r3_joint" type="revolute">
    <origin xyz="0 0 0" rpy="0 0 0" />
    <parent link="zarm_r2_link" />
    <child link="zarm_r3_link" />
    <axis xyz="0 0 1" />
    <limit lower="-1.5707963267949" upper="1.5707963267949" effort="37.0" velocity="15.0" />
    <dynamics damping="0.2" friction="0.0" />
  </joint>
  <transmission type="SimpleTransmission">
    <joint name="zarm_r3_joint" />
    <actuator name="zarm_r3_joint_motor" />
  </transmission>
  <link name="zarm_r4_link">
    <inertial>
      <origin xyz="-0.00081309 0.01331683 -0.08985563" rpy="0 0 0" />
      <mass value="0.42136972" />
      <inertia ixx="0.00335991" ixy="-0.00000193" ixz="0.00001686" iyy="0.00315848" iyz="-0.00008493" izz="0.00049447" />
    </inertial>
    <visual>
      <origin xyz="0 0 0" rpy="0 0 0" />
      <geometry>
        <mesh filename="../../meshes/r_forearm.STL" />
      </geometry>
      <material name="">
        <color rgba="1 1 1 1" />
      </material>
    </visual>
  </link>
  <joint name="zarm_r4_joint" type="revolute">
    <origin xyz="0 -0.0 -0.20533" rpy="0 0 0" />
    <parent link="zarm_r3_link" />
    <child link="zarm_r4_link" />
    <axis xyz="0 1 0" />
    <limit lower="-2.26892802759263" upper="0.08726" effort="37.0" velocity="15.0" />
    <dynamics damping="0.2" friction="0.0" />
  </joint>
  <transmission type="SimpleTransmission">
    <joint name="zarm_r4_joint" />
    <actuator name="zarm_r4_joint_motor" />
  </transmission>
  <link name="zarm_r7_end_effector">
    <collision>
      <origin rpy="0 0 0" xyz="0 0 0" />
      <geometry>
        <sphere radius="0.005" />
      </geometry>
    </collision>
  </link>
  <joint name="zarm_r7_end_effector_joint" type="fixed">
    <origin xyz="0 0.0 -0.2175" rpy="0 0 0" />
    <parent link="zarm_r4_link" />
    <child link="zarm_r7_end_effector" />
  </joint>
  <!-- end frame -->
  <!-- <frame link="l_hand_pitch" name="l_hand_sole" xyz="0 0 -0.1" /> -->
  <!-- end frame -->
  <!-- <frame link="r_hand_pitch" name="r_hand_sole" xyz="0 0 -0.1" /> -->
</robot>
