<?xml version="1.0" ?>
<!-- =================================================================================== -->
<!-- |    This document was autogenerated by xacro from /home/fandes/workspace/kuavo-ros-control/src/humanoid-control/humanoid_interface_drake/models/biped_gen4.2/urdf/biped_v3_full.xacro | -->
<!-- |    EDITING THIS FILE BY HAND IS NOT RECOMMENDED                                 | -->
<!-- =================================================================================== -->
<robot name="biped_v3_full" xmlns:drake="https://drake.mit.edu">
  <link name="torso">
    <inertial>
      <origin xyz="-0.006 0.0 0.145" rpy="0 0 0" />
      <mass value="11.9496" />
      <inertia ixx="0.104" ixy="0.0" ixz="0.0" iyy="0.084" iyz="0.0" izz="0.050" />
    </inertial>
    <visual>
      <origin xyz="0 0 0" rpy="0 0 0" />
      <geometry>
        <mesh filename="../../meshes/torso.STL" />
      </geometry>
      <material name="">
        <color rgba="1 1 1 1" />
      </material>
    </visual>
  </link>
  <link name="waist">
    <inertial>
      <origin xyz="0.001 0.0 -0.122" rpy="0 0 0" />
      <mass value="4.853" />
      <inertia ixx="0.023" ixy="0.0" ixz="0.0" iyy="0.015" iyz="0.0" izz="0.017" />
    </inertial>
    <visual>
      <origin xyz="0 0 0" rpy="0 0 0" />
      <geometry>
        <mesh filename="../../meshes/waist.STL" />
      </geometry>
      <material name="">
        <color rgba="1 1 1 1" />
      </material>
    </visual>
  </link>
  <joint name="waist" type="revolute">
    <origin xyz="0 0 0" rpy="0 0 0" />
    <parent link="torso" />
    <child link="waist" />
    <axis xyz="0 0 1" />
    <limit lower="-2.61799387799149" upper="2.61799387799149" effort="50" velocity="8.37333333333333" />
    <dynamics damping="0.2" friction="0.1" />
  </joint>
  <transmission type="SimpleTransmission">
    <joint name="waist" />
    <actuator name="waist_motor" />
  </transmission>
  <link name="leg_l1_link">
    <inertial>
      <origin xyz="-0.00063257 -0.03319679 0.03319679" rpy="0 0 0" />
      <mass value="0.62568928" />
      <inertia ixx="0.00115145" ixy="0.00002961" ixz="-0.00002972" iyy="0.00195562" iyz="0.00004384" izz="0.00194595" />
    </inertial>
    <visual>
      <origin xyz="0 0 0" rpy="0 0 0" />
      <geometry>
        <mesh filename="../../meshes/l_leg_pitch.STL" />
      </geometry>
      <material name="">
        <color rgba="1 1 1 1" />
      </material>
    </visual>
  </link>
  <joint name="leg_l1_joint" type="revolute">
    <origin xyz="0.0 0.12441237 -0.22115341" rpy="0 0 0" />
    <parent link="waist" />
    <child link="leg_l1_link" />
    <axis xyz="0 0.70711 -0.70711" />
    <limit lower="-3.228" upper="2.44346" effort="180" velocity="23.55" />
    <dynamics damping="0.2" friction="0.1" />
  </joint>
  <transmission type="SimpleTransmission">
    <joint name="leg_l1_joint" />
    <actuator name="leg_l1_joint_motor" />
  </transmission>
  <link name="leg_l2_link">
    <inertial>
      <origin xyz="0.00998392 0.00005405 -0.00920979" rpy="0 0 0" />
      <mass value="2.03159924" />
      <inertia ixx="0.00458902" ixy="0.00000651" ixz="-0.00013665" iyy="0.00412295" iyz="-0.00000554" izz="0.00339874" />
    </inertial>
    <visual>
      <origin xyz="0 0 0" rpy="0 0 0" />
      <geometry>
        <mesh filename="../../meshes/l_leg_roll.STL" />
      </geometry>
      <material name="">
        <color rgba="1 1 1 1" />
      </material>
    </visual>
  </link>
  <joint name="leg_l2_joint" type="revolute">
    <origin xyz="0 0 0" rpy="0 0 0" />
    <parent link="leg_l1_link" />
    <child link="leg_l2_link" />
    <axis xyz="1 0 0" />
    <limit lower="-0.837758" upper="2.40855" effort="100" velocity="41.3433333333333" />
    <dynamics damping="0.2" friction="0.1" />
  </joint>
  <transmission type="SimpleTransmission">
    <joint name="leg_l2_joint" />
    <actuator name="leg_l2_joint_motor" />
  </transmission>
  <link name="leg_l3_link">
    <inertial>
      <origin xyz="-0.01363906  -0.00133710 -0.15770370" rpy="0 0 0" />
      <mass value="3.38846623" />
      <inertia ixx="0.01398219" ixy="-0.00011841" ixz="-0.00249868" iyy="0.01516820" iyz="-0.00032906" izz="0.00563002" />
    </inertial>
    <visual>
      <origin xyz="0 0 0" rpy="0 0 0" />
      <geometry>
        <mesh filename="../../meshes/l_leg_yaw.STL" />
      </geometry>
      <material name="">
        <color rgba="1 1 1 1" />
      </material>
    </visual>
  </link>
  <joint name="leg_l3_joint" type="revolute">
    <origin xyz="0 0 0" rpy="0 0 0" />
    <parent link="leg_l2_link" />
    <child link="leg_l3_link" />
    <axis xyz="0 0 1" />
    <limit lower="-1.7453" upper="1.7453" effort="100" velocity="41.3433333333333" />
    <dynamics damping="0.2" friction="0.1" />
  </joint>
  <transmission type="SimpleTransmission">
    <joint name="leg_l3_joint" />
    <actuator name="leg_l3_joint_motor" />
  </transmission>
  <link name="leg_l4_link">
    <inertial>
      <origin xyz="0.02204595 0.00442347 -0.11473525" rpy="0 0 0" />
      <mass value="2.61852" />
      <inertia ixx="0.01197778" ixy="0.00020915" ixz="0.00023052" iyy="0.01216530" iyz="-0.00118030" izz="0.00311797" />
    </inertial>
    <visual>
      <origin xyz="0 0 0" rpy="0 0 0" />
      <geometry>
        <mesh filename="../../meshes/l_knee.STL" />
      </geometry>
      <material name="">
        <color rgba="1 1 1 1" />
      </material>
    </visual>
  </link>
  <joint name="leg_l4_joint" type="revolute">
    <origin xyz="-0.03 0 -0.213" rpy="0 0 0" />
    <parent link="leg_l3_link" />
    <child link="leg_l4_link" />
    <axis xyz="0 1 0" />
    <limit lower="-0.08726646" upper="2.530727" effort="180" velocity="23.55" />
    <dynamics damping="0.2" friction="0.1" />
  </joint>
  <transmission type="SimpleTransmission">
    <joint name="leg_l4_joint" />
    <actuator name="leg_l4_joint_motor" />
  </transmission>
  <link name="leg_l5_link">
    <inertial>
      <origin xyz="-0.00317025 0.00000108 -0.00652874" rpy="0 0 0" />
      <mass value="0.10854305" />
      <inertia ixx="0.00001902" ixy="0.0" ixz="-0.00000266" iyy="0.00002278" iyz="0.0" izz="0.00001170" />
    </inertial>
    <visual>
      <origin xyz="0 0 0" rpy="0 0 0" />
      <geometry>
        <mesh filename="../../meshes/l_foot_pitch.STL" />
      </geometry>
      <material name="">
        <color rgba="1 1 1 1" />
      </material>
    </visual>
  </link>
  <joint name="leg_l5_joint" type="revolute">
    <origin xyz="0.03 0 -0.276" rpy="0 0 0" />
    <parent link="leg_l4_link" />
    <child link="leg_l5_link" />
    <axis xyz="0 1 0" />
    <limit lower="-0.872664625997165" upper="0.523598775598299" effort="36.0" velocity="23.0266666666667" />
    <dynamics damping="0.2" friction="0.1" />
  </joint>
  <transmission type="SimpleTransmission">
    <joint name="leg_l5_joint" />
    <actuator name="leg_l5_joint_motor" />
  </transmission>
  <link name="leg_l6_link">
    <inertial>
      <origin xyz="0.02388909 0.00010137 -0.01697048" rpy="0 0 0" />
      <mass value="0.43610846" />
      <inertia ixx="0.00019972" ixy="-0.00000020" ixz="0.00007928" iyy="0.00097984" iyz="-0.00000083" izz="0.00106502" />
    </inertial>
    <visual>
      <origin xyz="0 0 0" rpy="0 0 0" />
      <geometry>
        <mesh filename="../../meshes/l_foot_roll.STL" />
      </geometry>
      <material name="">
        <color rgba="1 1 1 1" />
      </material>
    </visual>
  </link>
  <joint name="leg_l6_joint" type="revolute">
    <origin xyz="0 0 -0.018" rpy="0 0 0" />
    <parent link="leg_l5_link" />
    <child link="leg_l6_link" />
    <axis xyz="1 0 0" />
    <limit lower="-0.261799387799149" upper="0.261799387799149" effort="36" velocity="23.0266666666667" />
    <dynamics damping="0.2" friction="0.1" />
  </joint>
  <transmission type="SimpleTransmission">
    <joint name="leg_l6_joint" />
    <actuator name="leg_l6_joint_motor" />
  </transmission>
  <frame link="leg_l6_link" name="l_foot_sole" xyz="0.0 0.0 -0.03" />
  <frame link="leg_l6_link" name="l_foot_toe" xyz="0.1510 0.0 -0.03" />
  <frame link="leg_l6_link" name="l_foot_heel" xyz="-0.0538 0.0 -0.03" />
  <link name="leg_r1_link">
    <inertial>
      <origin xyz="-0.00211316 0.02890476 0.02937117" rpy="0 0 0" />
      <mass value="0.42877618" />
      <inertia ixx="0.00068733" ixy="-3.303e-05" ixz="-3.348e-05" iyy="0.00109695" iyz="-4.173e-05" izz="0.00108874" />
    </inertial>
    <visual>
      <origin xyz="0 0 0" rpy="0 0 0" />
      <geometry>
        <mesh filename="../../meshes/r_leg_pitch.STL" />
      </geometry>
      <material name="">
        <color rgba="1 1 1 1" />
      </material>
    </visual>
  </link>
  <joint name="leg_r1_joint" type="revolute">
    <origin xyz="0.0 -0.12441237 -0.22115341" rpy="0 0 0" />
    <parent link="waist" />
    <child link="leg_r1_link" />
    <axis xyz="0 -0.70711 -0.70711" />
    <limit lower="-3.228" upper="2.44346" effort="180" velocity="23.55" />
    <dynamics damping="0.2" friction="0.1" />
  </joint>
  <transmission type="SimpleTransmission">
    <joint name="leg_r1_joint" />
    <actuator name="leg_r1_joint_motor" />
  </transmission>
  <link name="leg_r2_link">
    <inertial>
      <origin xyz="0.00300817 1.847e-05 -0.05309364" rpy="0 0 0" />
      <mass value="2.4999594" />
      <inertia ixx="0.00728182" ixy="0" ixz="0" iyy="0.00721205" iyz="0" izz="0.00244863" />
    </inertial>
    <visual>
      <origin xyz="0 0 0" rpy="0 0 0" />
      <geometry>
        <mesh filename="../../meshes/r_leg_roll.STL" />
      </geometry>
      <material name="">
        <color rgba="1 1 1 1" />
      </material>
    </visual>
  </link>
  <joint name="leg_r2_joint" type="revolute">
    <origin xyz="0 0 0" rpy="0 0 0" />
    <parent link="leg_r1_link" />
    <child link="leg_r2_link" />
    <axis xyz="1 0 0" />
    <limit lower="-2.40855" upper="0.837758" effort="100" velocity="41.3433333333333" />
    <dynamics damping="0.2" friction="0.1" />
  </joint>
  <transmission type="SimpleTransmission">
    <joint name="leg_r2_joint" />
    <actuator name="leg_r2_joint_motor" />
  </transmission>
  <link name="leg_r3_link">
    <inertial>
      <origin xyz="-0.01363906  0.00133710 -0.15770370" rpy="0 0 0" />
      <mass value="3.38846623" />
      <inertia ixx="0.01398219" ixy="0.00011841" ixz="-0.00249868" iyy="0.01516820" iyz="0.00032906" izz="0.00563002" />
    </inertial>
    <visual>
      <origin xyz="0 0 0" rpy="0 0 0" />
      <geometry>
        <mesh filename="../../meshes/r_leg_yaw.STL" />
      </geometry>
      <material name="">
        <color rgba="1 1 1 1" />
      </material>
    </visual>
  </link>
  <joint name="leg_r3_joint" type="revolute">
    <origin xyz="0 0 0" rpy="0 0 0" />
    <parent link="leg_r2_link" />
    <child link="leg_r3_link" />
    <axis xyz="0 0 1" />
    <limit lower="-1.7453" upper="1.7453" effort="100" velocity="41.3433333333333" />
    <dynamics damping="0.2" friction="0.1" />
  </joint>
  <transmission type="SimpleTransmission">
    <joint name="leg_r3_joint" />
    <actuator name="leg_r3_joint_motor" />
  </transmission>
  <link name="leg_r4_link">
    <inertial>
      <origin xyz="0.02204595 -0.00442347 -0.11473525" rpy="0 0 0" />
      <mass value="2.61852" />
      <inertia ixx="0.01197778" ixy="-0.00020915" ixz="0.00023052" iyy="0.01216530" iyz="0.00118030" izz="0.00311797" />
    </inertial>
    <visual>
      <origin xyz="0 0 0" rpy="0 0 0" />
      <geometry>
        <mesh filename="../../meshes/r_knee.STL" />
      </geometry>
      <material name="">
        <color rgba="1 1 1 1" />
      </material>
    </visual>
  </link>
  <joint name="leg_r4_joint" type="revolute">
    <origin xyz="-0.03 0 -0.213" rpy="0 0 0" />
    <parent link="leg_r3_link" />
    <child link="leg_r4_link" />
    <axis xyz="0 1 0" />
    <limit lower="-0.08726646" upper="2.530727" effort="180" velocity="23.55" />
    <dynamics damping="0.2" friction="0.1" />
  </joint>
  <transmission type="SimpleTransmission">
    <joint name="leg_r4_joint" />
    <actuator name="leg_r4_joint_motor" />
  </transmission>
  <link name="leg_r5_link">
    <inertial>
      <origin xyz="-0.00317025 0.00000108 -0.00652874" rpy="0 0 0" />
      <mass value="0.10854305" />
      <inertia ixx="0.00001902" ixy="0.0" ixz="-0.00000266" iyy="0.00002278" iyz="0.0" izz="0.00001170" />
    </inertial>
    <visual>
      <origin xyz="0 0 0" rpy="0 0 0" />
      <geometry>
        <mesh filename="../../meshes/r_foot_pitch.STL" />
      </geometry>
      <material name="">
        <color rgba="1 1 1 1" />
      </material>
    </visual>
  </link>
  <joint name="leg_r5_joint" type="revolute">
    <origin xyz="0.03 0 -0.276" rpy="0 0 0" />
    <parent link="leg_r4_link" />
    <child link="leg_r5_link" />
    <axis xyz="0 1 0" />
    <limit lower="-0.872664625997165" upper="0.523598775598299" effort="36.0" velocity="23.0266666666667" />
    <dynamics damping="0.2" friction="0.1" />
  </joint>
  <transmission type="SimpleTransmission">
    <joint name="leg_r5_joint" />
    <actuator name="leg_r5_joint_motor" />
  </transmission>
  <link name="leg_r6_link">
    <inertial>
      <origin xyz="0.02388909 -0.00010137 -0.01697048" rpy="0 0 0" />
      <mass value="0.43610846" />
      <inertia ixx="0.00019972" ixy="0.00000020" ixz="0.00007928" iyy="0.00097984" iyz="0.00000083" izz="0.00106502" />
    </inertial>
    <visual>
      <origin xyz="0 0 0" rpy="0 0 0" />
      <geometry>
        <mesh filename="../../meshes/r_foot_roll.STL" />
      </geometry>
      <material name="">
        <color rgba="1 1 1 1" />
      </material>
    </visual>
  </link>
  <joint name="leg_r6_joint" type="revolute">
    <origin xyz="0 0 -0.018" rpy="0 0 0" />
    <parent link="leg_r5_link" />
    <child link="leg_r6_link" />
    <axis xyz="1 0 0" />
    <limit lower="-0.261799387799149" upper="0.261799387799149" effort="36" velocity="23.0266666666667" />
    <dynamics damping="0.2" friction="0.1" />
  </joint>
  <transmission type="SimpleTransmission">
    <joint name="leg_r6_joint" />
    <actuator name="leg_r6_joint_motor" />
  </transmission>
  <frame link="leg_r6_link" name="r_foot_sole" xyz="0.0 0.0 -0.03" />
  <frame link="leg_r6_link" name="r_foot_toe" xyz="0.1510 0.0 -0.03" />
  <frame link="leg_r6_link" name="r_foot_heel" xyz="-0.0538 0.0 -0.03" />
  <!-- =========================================================== Arms ================================================================= -->
   <link name="zarm_l1_link">
    <inertial>
      <origin xyz="0.01852427 -0.00307832 -0.00006089" rpy="0 0 0" />
      <mass value="0.80328906" />
      <inertia ixx="0.00065573" ixy="-0.00004427" ixz="-0.00000010" iyy="0.00082825" iyz="-0.00000114" izz="0.00093564" />
    </inertial>
    <visual>
      <origin xyz="0 0 0" rpy="0 0 0" />
      <geometry>
        <mesh filename="../../meshes/l_arm_pitch.STL" />
      </geometry>
      <material name="">
        <color rgba="1 1 1 1" />
      </material>
    </visual>
  </link>
  <joint name="zarm_l1_joint" type="revolute">
    <origin xyz="0.0 0.18100293 0.23992606" rpy="0 0 0" />
    <parent link="torso" />
    <child link="zarm_l1_link" />
    <axis xyz="0 1 0" />
    <limit lower="-3.14159265358979" upper="2.0943951023932" effort="12" velocity="7.32666666666667" />
    <dynamics damping="0.2" friction="0.1" />
  </joint>
  <transmission type="SimpleTransmission">
    <joint name="zarm_l1_joint" />
    <actuator name="zarm_l1_joint_motor" />
  </transmission>
  <link name="zarm_l2_link">
    <inertial>
      <origin xyz="0.00217668 0.00574680 -0.03258678" rpy="0 0 0" />
      <mass value="0.32360735" />
      <inertia ixx="0.00046909" ixy="0.0" ixz="-0.00002559" iyy="0.00068110" iyz="0.0" izz="0.00049735" />
    </inertial>
    <visual>
      <origin xyz="0 0 0" rpy="0 0 0" />
      <geometry>
        <mesh filename="../../meshes/l_arm_roll.STL" />
      </geometry>
      <material name="">
        <color rgba="1 1 1 1" />
      </material>
    </visual>
  </link>
  <joint name="zarm_l2_joint" type="revolute">
    <origin xyz="0 0 0" rpy="0.17453 0 0" />
    <parent link="zarm_l1_link" />
    <child link="zarm_l2_link" />
    <axis xyz="1 0 0" />
    <limit lower="-0.52" upper="3.316" effort="12" velocity="7.32666666666667" />
    <dynamics damping="0.2" friction="0.1" />
  </joint>
  <transmission type="SimpleTransmission">
    <joint name="zarm_l2_joint" />
    <actuator name="zarm_l2_joint_motor" />
  </transmission>
  <link name="zarm_l3_link">
    <inertial>
      <origin xyz="-0.00006747 -0.01016408 -0.15041767" rpy="0 0 0" />
      <mass value="1.46578996" />
      <inertia ixx="0.00696550" ixy="0.00000046" ixz="0.00000200" iyy="0.00656301" iyz="-0.00085646" izz="0.00135717" />
    </inertial>
    <visual>
      <origin xyz="0 0 0" rpy="0 0 0" />
      <geometry>
        <mesh filename="../../meshes/l_arm_yaw.STL" />
      </geometry>
      <material name="">
        <color rgba="1 1 1 1" />
      </material>
    </visual>
  </link>
  <joint name="zarm_l3_joint" type="revolute">
    <origin xyz="0 0 0" rpy="0 0 0" />
    <parent link="zarm_l2_link" />
    <child link="zarm_l3_link" />
    <axis xyz="0 0 1" />
    <limit lower="-1.5707963267949" upper="1.5707963267949" effort="12" velocity="7.32666666666667" />
    <dynamics damping="0.2" friction="0.1" />
  </joint>
  <transmission type="SimpleTransmission">
    <joint name="zarm_l3_joint" />
    <actuator name="zarm_l3_joint_motor" />
  </transmission>
  <link name="zarm_l4_link">
    <inertial>
      <origin xyz="-0.00081309 -0.01331683 -0.08985563" rpy="0 0 0" />
      <mass value="0.42136972" />
      <inertia ixx="0.00335991" ixy="0.00000193" ixz="0.00001686" iyy="0.00315848" iyz="0.00008493" izz="0.00049447" />
    </inertial>
    <visual>
      <origin xyz="0 0 0" rpy="0 0 0" />
      <geometry>
        <mesh filename="../../meshes/l_forearm.STL" />
      </geometry>
      <material name="">
        <color rgba="1 1 1 1" />
      </material>
    </visual>
  </link>
  <joint name="zarm_l4_joint" type="revolute">
    <origin xyz="0 0.0 -0.20533" rpy="0 0 0" />
    <parent link="zarm_l3_link" />
    <child link="zarm_l4_link" />
    <axis xyz="0 1 0" />
    <limit lower="-2.26892802759263" upper="0.08726" effort="12" velocity="7.32666666666667" />
    <dynamics damping="0.2" friction="0.1" />
  </joint>
  <transmission type="SimpleTransmission">
    <joint name="zarm_l4_joint" />
    <actuator name="zarm_l4_joint_motor" />
  </transmission>
  <link name="zarm_r1_link">
    <inertial>
      <origin xyz="0.01852427 0.00307832 -0.00006089" rpy="0 0 0" />
      <mass value="0.80328906" />
      <inertia ixx="0.00065573" ixy="0.00004427" ixz="-0.00000010" iyy="0.00082825" iyz="0.00000114" izz="0.00093564" />
    </inertial>
    <visual>
      <origin xyz="0 0 0" rpy="0 0 0" />
      <geometry>
        <mesh filename="../../meshes/r_arm_pitch.STL" />
      </geometry>
      <material name="">
        <color rgba="1 1 1 1" />
      </material>
    </visual>
  </link>
  <joint name="zarm_r1_joint" type="revolute">
    <origin xyz="0.0 -0.18100293 0.23992606" rpy="0 0 0" />
    <parent link="torso" />
    <child link="zarm_r1_link" />
    <axis xyz="0 1 0" />
    <limit lower="-3.14159265358979" upper="2.0943951023932" effort="12" velocity="7.32666666666667" />
    <dynamics damping="0.2" friction="0.1" />
  </joint>
  <transmission type="SimpleTransmission">
    <joint name="zarm_r1_joint" />
    <actuator name="zarm_r1_joint_motor" />
  </transmission>
  <link name="zarm_r2_link">
    <inertial>
      <origin xyz="0.00217668 -0.00574680 -0.03258678" rpy="0 0 0" />
      <mass value="0.32360735" />
      <inertia ixx="0.00046909" ixy="0.0" ixz="-0.00002559" iyy="0.00068110" iyz="0.0" izz="0.00049735" />
    </inertial>
    <visual>
      <origin xyz="0 0 0" rpy="0 0 0" />
      <geometry>
        <mesh filename="../../meshes/r_arm_roll.STL" />
      </geometry>
      <material name="">
        <color rgba="1 1 1 1" />
      </material>
    </visual>
  </link>
  <joint name="zarm_r2_joint" type="revolute">
    <origin xyz="0 0 0" rpy="-0.17453 0 0" />
    <parent link="zarm_r1_link" />
    <child link="zarm_r2_link" />
    <axis xyz="1 0 0" />
    <limit lower="-3.3161" upper="0.52" effort="12" velocity="7.32666666666667" />
    <dynamics damping="0.2" friction="0.1" />
  </joint>
  <transmission type="SimpleTransmission">
    <joint name="zarm_r2_joint" />
    <actuator name="zarm_r2_joint_motor" />
  </transmission>
  <link name="zarm_r3_link">
    <inertial>
      <origin xyz="-0.00006747 0.01016408 -0.15041767" rpy="0 0 0" />
      <mass value="1.46578996" />
      <inertia ixx="0.00696550" ixy="-0.00000046" ixz="0.00000200" iyy="0.00656301" iyz="0.00085646" izz="0.00135717" />
    </inertial>
    <visual>
      <origin xyz="0 0 0" rpy="0 0 0" />
      <geometry>
        <mesh filename="../../meshes/r_arm_yaw.STL" />
      </geometry>
      <material name="">
        <color rgba="1 1 1 1" />
      </material>
    </visual>
  </link>
  <joint name="zarm_r3_joint" type="revolute">
    <origin xyz="0 0 0" rpy="0 0 0" />
    <parent link="zarm_r2_link" />
    <child link="zarm_r3_link" />
    <axis xyz="0 0 1" />
    <limit lower="-1.5707963267949" upper="1.5707963267949" effort="12" velocity="7.32666666666667" />
    <dynamics damping="0.2" friction="0.1" />
  </joint>
  <transmission type="SimpleTransmission">
    <joint name="zarm_r3_joint" />
    <actuator name="zarm_r3_joint_motor" />
  </transmission>
  <link name="zarm_r4_link">
    <inertial>
      <origin xyz="-0.00081309 0.01331683 -0.08985563" rpy="0 0 0" />
      <mass value="0.42136972" />
      <inertia ixx="0.00335991" ixy="-0.00000193" ixz="0.00001686" iyy="0.00315848" iyz="-0.00008493" izz="0.00049447" />
    </inertial>
    <visual>
      <origin xyz="0 0 0" rpy="0 0 0" />
      <geometry>
        <mesh filename="../../meshes/r_forearm.STL" />
      </geometry>
      <material name="">
        <color rgba="1 1 1 1" />
      </material>
    </visual>
  </link>
  <joint name="zarm_r4_joint" type="revolute">
    <origin xyz="0 -0.0 -0.20533" rpy="0 0 0" />
    <parent link="zarm_r3_link" />
    <child link="zarm_r4_link" />
    <axis xyz="0 1 0" />
    <limit lower="-2.26892802759263" upper="0.08726" effort="12" velocity="7.32666666666667" />
    <dynamics damping="0.2" friction="0.1" />
  </joint>
  <transmission type="SimpleTransmission">
    <joint name="zarm_r4_joint" />
    <actuator name="zarm_r4_joint_motor" />
  </transmission>
  <!-- end frame -->
  <!-- <frame link="l_hand_pitch" name="l_hand_sole" xyz="0 0 -0.1" /> -->
  <!-- end frame -->
  <!-- <frame link="r_hand_pitch" name="r_hand_sole" xyz="0 0 -0.1" /> -->
</robot>

