<mujoco model="biped_s17">
  <compiler angle="radian" meshdir="../meshes/"/>
  <default>
    <default class="collision">
      <geom material="collision" contype="1" conaffinity="1" user="2" rgba="0.9 0.3 0.3 0.2"/>
    </default>
  </default>
  <asset>
    <material name="collision"/>
    <mesh name="torso" file="torso.STL"/>
    <mesh name="waist" file="waist.STL"/>
    <mesh name="l_leg_pitch" file="l_leg_pitch.STL"/>
    <mesh name="l_leg_roll" file="l_leg_roll.STL"/>
    <mesh name="l_leg_yaw" file="l_leg_yaw.STL"/>
    <mesh name="l_knee" file="l_knee.STL"/>
    <mesh name="l_foot_pitch" file="l_foot_pitch.STL"/>
    <mesh name="l_foot_roll" file="l_foot_roll.STL"/>
    <mesh name="r_leg_pitch" file="r_leg_pitch.STL"/>
    <mesh name="r_leg_roll" file="r_leg_roll.STL"/>
    <mesh name="r_leg_yaw" file="r_leg_yaw.STL"/>
    <mesh name="r_knee" file="r_knee.STL"/>
    <mesh name="r_foot_pitch" file="r_foot_pitch.STL"/>
    <mesh name="r_foot_roll" file="r_foot_roll.STL"/>
    <mesh name="l_arm_pitch" file="l_arm_pitch.STL"/>
    <mesh name="l_arm_roll" file="l_arm_roll.STL"/>
    <mesh name="l_arm_yaw" file="l_arm_yaw.STL"/>
    <mesh name="l_forearm" file="l_forearm.STL"/>
    <mesh name="r_arm_pitch" file="r_arm_pitch.STL"/>
    <mesh name="r_arm_roll" file="r_arm_roll.STL"/>
    <mesh name="r_arm_yaw" file="r_arm_yaw.STL"/>
    <mesh name="r_forearm" file="r_forearm.STL"/>
    <mesh name="head_yaw" file="head_yaw.STL"/>
    <mesh name="head_pitch" file="head_pitch.STL"/>
  </asset>

  <worldbody>
    <body name="base_link">
      <inertial pos="0.001 0 -0.122" quat="0.707107 0.707107 0 0" mass="4.8567" diaginertia="0.023 0.017 0.015"/>
      <joint name="dummy_to_base_link" type="free" limited="false" actuatorfrclimited="false"/>
      <geom type="mesh" contype="0" conaffinity="0" group="1" density="0" rgba="1 1 1 1" mesh="waist"/>
      <geom size="0.08" pos="0.005 0 -0.12" quat="0.923764 0.382961 0 0" class="collision"/>

      <body name="leg_l1_link" pos="0 0.124412 -0.221153">
          <inertial pos="-0.00063257 -0.0331968 0.0331968" quat="0.306976 0.638057 0.270546 0.652268" mass="0.625689" diaginertia="0.0019949 0.001909 0.00114913"/>
          <joint name="leg_l1_joint" pos="0 0 0" axis="0 0.707107 -0.707107" range="-3.228 2.44346" actuatorfrcrange="-150 150" armature="0.003" damping="0.2" frictionloss="0.2"/>
          <geom type="mesh" contype="0" conaffinity="0" group="1" density="0" rgba="1 1 1 1" mesh="l_leg_pitch"/>
          <geom size="0.042 0.03" pos="-0.035 -0.02 0.02" quat="0.923764 0.382961 0 0" type="capsule" class="collision"/>
          <geom size="0.042 0.03" pos="0.035 -0.02 0.02" quat="0.923764 0.382961 0 0" type="capsule" class="collision"/>
          <body name="leg_l2_link">
            <inertial pos="0.00998392 5.405e-05 -0.00920979" quat="0.998376 -0.00280518 0.0563977 0.00753194" mass="2.0316" diaginertia="0.00460461 0.00412288 0.00338322"/>
            <joint name="leg_l2_joint" pos="0 0 0" axis="1 0 0" range="-0.837758 2.40855" actuatorfrcrange="-150 150" armature="0.003" damping="0.2" frictionloss="0.2"/>
            <geom type="mesh" contype="0" conaffinity="0" group="1" density="0" rgba="1 1 1 1" mesh="l_leg_roll"/>
            <geom size="0.055 0.07" pos="0 0 -0.065" type="capsule" class="collision"/>
            <body name="leg_l3_link">
              <inertial pos="-0.0136391 -0.0013371 -0.157704" quat="0.680483 0.0858738 0.104775 0.720132" mass="3.38847" diaginertia="0.0151815 0.0146713 0.0049277"/>
              <joint name="leg_l3_joint" pos="0 0 0" axis="0 0 1" range="-1.7453 1.7453" actuatorfrcrange="-70 70" armature="0.003" damping="0.2" frictionloss="0.2"/>
              <geom type="mesh" contype="0" conaffinity="0" group="1" density="0" rgba="1 1 1 1" mesh="l_leg_yaw"/>
              <geom size="0.055 0.015" pos="-0.025 0 -0.21" quat="0.707388 0.706825 0 0" type="capsule" class="collision"/>
              <body name="leg_l4_link" pos="-0.03 0 -0.213">
                <inertial pos="0.022046 0.00442347 -0.114735" quat="0.834057 -0.0612911 0.0232855 0.547768" mass="2.61852" diaginertia="0.0123942 0.0119075 0.0029593"/>
                <joint name="leg_l4_joint" pos="0 0 0" axis="0 1 0" range="-0.0872665 2.53073" actuatorfrcrange="-150 150" armature="0.003" damping="0.2" frictionloss="0.2"/>
                <geom type="mesh" contype="0" conaffinity="0" group="1" density="0" rgba="1 1 1 1" mesh="l_knee"/>
                <geom size="0.05 0.075" pos="0.021 0 -0.17" type="capsule" class="collision"/>
                <geom size="0.005 0.025" pos="0.068 0 -0.02" quat="0.707388 0.706825 0 0" type="capsule" class="collision"/>
                <geom size="0.005 0.025" pos="0.074 0 -0.05" quat="0.707388 0.706825 0 0" type="capsule" class="collision"/>
                <body name="leg_l5_link" pos="0.03 0 -0.276">
                  <inertial pos="-0.00317025 1.08e-06 -0.00652874" quat="0.698397 0.110643 0.110643 0.698397" mass="0.108543" diaginertia="2.278e-05 1.98845e-05 1.08355e-05"/>
                  <joint name="leg_l5_joint" pos="0 0 0" axis="0 1 0" range="-0.872665 0.523599" actuatorfrcrange="-74 74" armature="0.003" damping="0.2" frictionloss="0.2"/>
                  <geom type="mesh" contype="0" conaffinity="0" group="1" density="0" rgba="1 1 1 1" mesh="l_foot_pitch"/>
                  <body name="leg_l6_link" pos="0 0 -0.018">
                    <inertial pos="0.0238891 0.00010137 -0.0169705" quat="-0.00314074 0.7384 -0.00332222 0.674348" mass="0.436108" diaginertia="0.00107223 0.000979832 0.000192516"/>
                    <joint name="leg_l6_joint" pos="0 0 0" axis="1 0 0" range="-0.261799 0.261799" actuatorfrcrange="-74 74" armature="0.003" damping="0.2" frictionloss="0.2"/>
                    <geom type="mesh" contype="0" conaffinity="0" group="1" density="0" rgba="1 1 1 1" mesh="l_foot_roll"/>
                    <geom size="0.035 0.005" pos="-0.02 0 -0.035" type="cylinder" class="collision"/>
                    <geom size="0.04 0.005" pos="0.11 0 -0.035" type="cylinder" class="collision"/>
                    <geom size="0.06 0.035 0.005" pos="0.038 0 -0.035" type="box" class="collision"/>
                  </body>
                </body>
              </body>
            </body>
          </body>
        </body>
        <body name="leg_r1_link" pos="0 -0.124412 -0.221153">
          <inertial pos="-0.00063257 0.0331968 0.0331968" quat="0.652268 0.270546 0.638057 0.306976" mass="0.625689" diaginertia="0.0019949 0.001909 0.00114913"/>
          <joint name="leg_r1_joint" pos="0 0 0" axis="0 -0.707107 -0.707107" range="-2.44346 3.228" actuatorfrcrange="-150 150" armature="0.003" damping="0.2" frictionloss="0.2"/>
          <geom type="mesh" contype="0" conaffinity="0" group="1" density="0" rgba="1 1 1 1" mesh="r_leg_pitch"/>
          <geom size="0.042 0.03" pos="-0.035 0.02 0.02" quat="0.923764 -0.382961 0 0" type="capsule" class="collision"/>
          <geom size="0.042 0.03" pos="0.035 0.02 0.02" quat="0.923764 -0.382961 0 0" type="capsule" class="collision"/>
          <body name="leg_r2_link">
            <inertial pos="0.00998392 -5.405e-05 -0.00920979" quat="0.998376 0.00280518 0.0563977 -0.00753194" mass="2.0316" diaginertia="0.00460461 0.00412288 0.00338322"/>
            <joint name="leg_r2_joint" pos="0 0 0" axis="1 0 0" range="-2.40855 0.837758" actuatorfrcrange="-150 150" armature="0.003" damping="0.2" frictionloss="0.2"/>
            <geom type="mesh" contype="0" conaffinity="0" group="1" density="0" rgba="1 1 1 1" mesh="r_leg_roll"/>
            <geom size="0.055 0.07" pos="0 0 -0.065" type="capsule" class="collision"/>
            <body name="leg_r3_link">
              <inertial pos="-0.0136391 0.0013371 -0.157704" quat="0.720132 0.104775 0.0858738 0.680483" mass="3.38847" diaginertia="0.0151815 0.0146713 0.0049277"/>
              <joint name="leg_r3_joint" pos="0 0 0" axis="0 0 1" range="-1.7453 1.7453" actuatorfrcrange="-70 70" armature="0.003" damping="0.2" frictionloss="0.2"/>
              <geom type="mesh" contype="0" conaffinity="0" group="1" density="0" rgba="1 1 1 1" mesh="r_leg_yaw"/>
              <geom size="0.055 0.015" pos="-0.025 0 -0.21" quat="0.707388 0.706825 0 0" type="capsule" class="collision"/>
              <body name="leg_r4_link" pos="-0.03 0 -0.213">
                <inertial pos="0.022046 -0.00442347 -0.114735" quat="0.547768 0.0232855 -0.0612911 0.834057" mass="2.61852" diaginertia="0.0123942 0.0119075 0.0029593"/>
                <joint name="leg_r4_joint" pos="0 0 0" axis="0 1 0" range="-0.0872665 2.53073" actuatorfrcrange="-150 150" armature="0.003" damping="0.2" frictionloss="0.2"/>
                <geom type="mesh" contype="0" conaffinity="0" group="1" density="0" rgba="1 1 1 1" mesh="r_knee"/>
                <geom size="0.05 0.075" pos="0.021 0 -0.17" type="capsule" class="collision"/>
                <geom size="0.005 0.025" pos="0.068 0 -0.02" quat="0.707388 0.706825 0 0" type="capsule" class="collision"/>
                <geom size="0.005 0.025" pos="0.074 0 -0.05" quat="0.707388 0.706825 0 0" type="capsule" class="collision"/>
                <body name="leg_r5_link" pos="0.03 0 -0.276">
                  <inertial pos="-0.00317025 1.08e-06 -0.00652874" quat="0.698397 0.110643 0.110643 0.698397" mass="0.108543" diaginertia="2.278e-05 1.98845e-05 1.08355e-05"/>
                  <joint name="leg_r5_joint" pos="0 0 0" axis="0 1 0" range="-0.872665 0.523599" actuatorfrcrange="-74 74" armature="0.003" damping="0.2" frictionloss="0.2"/>
                  <geom type="mesh" contype="0" conaffinity="0" group="1" density="0" rgba="1 1 1 1" mesh="r_foot_pitch"/>
                  <body name="leg_r6_link" pos="0 0 -0.018">
                    <inertial pos="0.0238891 -0.00010137 -0.0169705" quat="0.00314074 0.7384 0.00332222 0.674348" mass="0.436108" diaginertia="0.00107223 0.000979832 0.000192516"/>
                    <joint name="leg_r6_joint" pos="0 0 0" axis="1 0 0" range="-0.261799 0.261799" actuatorfrcrange="-74 74" armature="0.003" damping="0.2" frictionloss="0.2"/>
                    <geom type="mesh" contype="0" conaffinity="0" group="1" density="0" rgba="1 1 1 1" mesh="r_foot_roll"/>
                    <geom size="0.035 0.005" pos="-0.02 0 -0.035" type="cylinder" class="collision"/>
                    <geom size="0.04 0.005" pos="0.11 0 -0.035" type="cylinder" class="collision"/>
                    <geom size="0.06 0.035 0.005" pos="0.038 0 -0.035" type="box" class="collision"/>
                  </body>
                </body>
              </body>
            </body>
          </body>
        </body>
      <body name="waist_yaw_link">
        <site name="imu" pos="0 0 0" />
        <inertial pos="-0.006 0 0.145" mass="10.8490" diaginertia="0.104 0.084 0.05"/>
        <joint name="waist_yaw_joint" pos="0 0 0" axis="0 0 1" range="-2.61799 2.61799" actuatorfrcrange="-50 50" armature="0.003" damping="0.2" frictionloss="0.2"/>
        <geom type="mesh" contype="0" conaffinity="0" group="1" density="0" rgba="1 1 1 1" mesh="torso"/>
        <geom size="0.07 0.1 0.13" pos="0.01 0 0.14" type="box" class="collision"/>
        <geom size="0.008 0.0625" pos="-0.102 0 0.288" quat="0.707105 0.707108 0 0" type="cylinder" class="collision"/>
        <body name="zarm_l1_link" pos="0 0.181003 0.239926">
          <inertial pos="0.0185243 -0.00307832 -6.089e-05" quat="-0.0876185 0.702161 0.0796388 0.702105" mass="0.803289" diaginertia="0.000935653 0.000838935 0.000645033"/>
          <joint name="zarm_l1_joint" pos="0 0 0" axis="0 1 0" range="-3.14159 2.0944" actuatorfrcrange="-14.1 14.1" armature="0.003" damping="0.2" frictionloss="0.2"/>
          <geom type="mesh" contype="0" conaffinity="0" group="1" density="0" rgba="1 1 1 1" mesh="l_arm_pitch"/>
          <geom size="0.04 0.02" quat="0.707105 0 0.707108 0" type="capsule" class="collision"/>
          <body name="zarm_l2_link" quat="0.996195 0.0871543 0 0">
            <inertial pos="0.00217668 0.0057468 -0.0325868" quat="0.614053 0.350627 0.350627 0.614053" mass="0.323607" diaginertia="0.0006811 0.000512452 0.000453988"/>
            <joint name="zarm_l2_joint" pos="0 0 0" axis="1 0 0" range="-0.52 3.316" actuatorfrcrange="-37 37" armature="0.003" damping="0.2" frictionloss="0.2"/>
            <geom type="mesh" contype="0" conaffinity="0" group="1" density="0" rgba="1 1 1 1" mesh="l_arm_roll"/>
            <geom size="0.035 0.0175" pos="0 0 -0.0525" type="capsule" class="collision"/>
            <body name="zarm_l3_link">
              <inertial pos="-6.747e-05 -0.0101641 -0.150418" quat="0.996844 -0.0793864 -0.000157022 0.000272857" mass="1.46579" diaginertia="0.0069655 0.00670029 0.00121989"/>
              <joint name="zarm_l3_joint" pos="0 0 0" axis="0 0 1" range="-1.5708 1.5708" actuatorfrcrange="-37 37" armature="0.003" damping="0.2" frictionloss="0.2"/>
              <geom type="mesh" contype="0" conaffinity="0" group="1" density="0" rgba="1 1 1 1" mesh="l_arm_yaw"/>
              <geom size="0.035 0.025" pos="0 0 -0.125" type="capsule" class="collision"/>
              <body name="zarm_l4_link" pos="0 0 -0.20533">
                <inertial pos="-0.000812081 -0.0133003 -0.090014" quat="0.999848 0.0160124 -0.00302648 0.00615008" mass="0.421893" diaginertia="0.00336866 0.00316973 0.000491717"/>
                <joint name="zarm_l4_joint" pos="0 0 0" axis="0 1 0" range="-2.26893 0.08726" actuatorfrcrange="-37 37" armature="0.003" damping="0.2" frictionloss="0.2"/>
                <geom type="mesh" contype="0" conaffinity="0" group="1" density="0" rgba="1 1 1 1" mesh="l_forearm"/>
                <geom size="0.045 0.015" quat="0.707388 0.706825 0 0" type="capsule" class="collision"/>
                <geom size="0.02 0.06" pos="0 0 -0.1" type="capsule" class="collision"/>
                <geom size="0.03" pos="0 0 -0.2175" class="collision" friction="0.0001 0.005 0.0001"/>
                <geom size="0.005" pos="0 0 -0.2175" type="sphere" class="collision"/>
              </body>
            </body>
          </body>
        </body>
        <body name="zarm_r1_link" pos="0 -0.181003 0.239926">
          <inertial pos="0.0185243 0.00307832 -6.089e-05" quat="0.0876185 0.702161 -0.0796388 0.702105" mass="0.803289" diaginertia="0.000935653 0.000838935 0.000645033"/>
          <joint name="zarm_r1_joint" pos="0 0 0" axis="0 1 0" range="-3.14159 2.0944" actuatorfrcrange="-14.1 14.1" armature="0.003" damping="0.2" frictionloss="0.2"/>
          <geom type="mesh" contype="0" conaffinity="0" group="1" density="0" rgba="1 1 1 1" mesh="r_arm_pitch"/>
          <geom size="0.04 0.02" quat="0.707105 0 0.707108 0" type="capsule" class="collision"/>
          <body name="zarm_r2_link" quat="0.996195 -0.0871543 0 0">
            <inertial pos="0.00217668 -0.0057468 -0.0325868" quat="0.614053 0.350627 0.350627 0.614053" mass="0.323607" diaginertia="0.0006811 0.000512452 0.000453988"/>
            <joint name="zarm_r2_joint" pos="0 0 0" axis="1 0 0" range="-3.3161 0.52" actuatorfrcrange="-37 37" armature="0.003" damping="0.2" frictionloss="0.2"/>
            <geom type="mesh" contype="0" conaffinity="0" group="1" density="0" rgba="1 1 1 1" mesh="r_arm_roll"/>
            <geom size="0.035 0.0175" pos="0 0 -0.0525" type="capsule" class="collision"/>
            <body name="zarm_r3_link">
              <inertial pos="-6.747e-05 0.0101641 -0.150418" quat="0.996844 0.0793864 -0.000157022 -0.000272857" mass="1.46579" diaginertia="0.0069655 0.00670029 0.00121989"/>
              <joint name="zarm_r3_joint" pos="0 0 0" axis="0 0 1" range="-1.5708 1.5708" actuatorfrcrange="-37 37" armature="0.003" damping="0.2" frictionloss="0.2"/>
              <geom type="mesh" contype="0" conaffinity="0" group="1" density="0" rgba="1 1 1 1" mesh="r_arm_yaw"/>
              <geom size="0.035 0.025" pos="0 0 -0.125" type="capsule" class="collision"/>
              <body name="zarm_r4_link" pos="0 0 -0.20533">
                <inertial pos="-0.000812081 0.0133003 -0.090014" quat="0.999848 -0.0160124 -0.00302648 -0.00615008" mass="0.421893" diaginertia="0.00336866 0.00316973 0.000491717"/>
                <joint name="zarm_r4_joint" pos="0 0 0" axis="0 1 0" range="-2.26893 0.08726" actuatorfrcrange="-37 37" armature="0.003" damping="0.2" frictionloss="0.2"/>
                <geom type="mesh" contype="0" conaffinity="0" group="1" density="0" rgba="1 1 1 1" mesh="r_forearm"/>
                <geom size="0.045 0.015" quat="0.707388 0.706825 0 0" type="capsule" class="collision"/>
                <geom size="0.02 0.06" pos="0 0 -0.1" type="capsule" class="collision"/>
                <geom size="0.03" pos="0 0 -0.2175" class="collision" friction="0.0001 0.005 0.0001"/>
                <geom size="0.005" pos="0 0 -0.2175" type="sphere" class="collision"/>
              </body>
            </body>
          </body>
        </body>
        <body name="zhead_1_link" pos="0.004 0 0.35618">
          <inertial pos="-0.00081546 0.00754474 0.0168097" mass="1.03078" diaginertia="0.002156 0.00189151 0.00071659"/>
          <joint name="zhead_1_joint" pos="0 0 0" axis="0 0 1" range="-1.5708 1.5708" actuatorfrcrange="-1.5 1.5" armature="0.003" damping="0.2" frictionloss="0.2"/>
          <geom type="mesh" contype="0" conaffinity="0" group="1" density="0" rgba="1 1 1 1" mesh="head_yaw"/>
          <geom size="0.035 0.05" type="capsule" class="collision"/>
          <body name="zhead_2_link">
            <inertial pos="0.014664 0.00044662 0.0574289" quat="0 0.707107 0 0.707107" mass="0.33655" diaginertia="0.00150717 0.00141557 0.00119625"/>
            <joint name="zhead_2_joint" pos="0 0 0" axis="0 1 0" range="-0.349066 0.785398" actuatorfrcrange="-12 12" armature="0.003" damping="0.2" frictionloss="0.2"/>
            <geom type="mesh" contype="0" conaffinity="0" group="1" density="0" rgba="1 1 1 1" mesh="head_pitch"/>
            <geom size="0.075" pos="0 0 0.035" class="collision"/>
          </body>
        </body>
      </body>
    </body>
  </worldbody>
  <actuator>
    <motor gear="1" joint="leg_l1_joint" name="leg_l1_joint_motor" ctrllimited="true" ctrlrange="-150 150" />
    <motor gear="1" joint="leg_l2_joint" name="leg_l2_joint_motor" ctrllimited="true" ctrlrange="-150 150" />
    <motor gear="1" joint="leg_l3_joint" name="leg_l3_joint_motor" ctrllimited="true" ctrlrange="-70 70" />
    <motor gear="1" joint="leg_l4_joint" name="leg_l4_joint_motor" ctrllimited="true" ctrlrange="-150 150" />
    <motor gear="1" joint="leg_l5_joint" name="leg_l5_joint_motor" ctrllimited="true" ctrlrange="-74 74" />
    <motor gear="1" joint="leg_l6_joint" name="leg_l6_joint_motor" ctrllimited="true" ctrlrange="-74 74" />
    <motor gear="1" joint="leg_r1_joint" name="leg_r1_joint_motor" ctrllimited="true" ctrlrange="-150 150" />
    <motor gear="1" joint="leg_r2_joint" name="leg_r2_joint_motor" ctrllimited="true" ctrlrange="-150 150" />
    <motor gear="1" joint="leg_r3_joint" name="leg_r3_joint_motor" ctrllimited="true" ctrlrange="-70 70" />
    <motor gear="1" joint="leg_r4_joint" name="leg_r4_joint_motor" ctrllimited="true" ctrlrange="-150 150" />
    <motor gear="1" joint="leg_r5_joint" name="leg_r5_joint_motor" ctrllimited="true" ctrlrange="-74 74" />
    <motor gear="1" joint="leg_r6_joint" name="leg_r6_joint_motor" ctrllimited="true" ctrlrange="-74 74" />
    <motor gear="1" joint="waist_yaw_joint" name="waist_yaw_joint_motor" ctrllimited="true" ctrlrange="-80 80" />
    <motor gear="1" joint="zarm_l1_joint" name="zarm_l1_joint_motor" ctrllimited="true" ctrlrange="-14.1 14.1" />
    <motor gear="1" joint="zarm_l2_joint" name="zarm_l2_joint_motor" ctrllimited="true" ctrlrange="-37 37" />
    <motor gear="1" joint="zarm_l3_joint" name="zarm_l3_joint_motor" ctrllimited="true" ctrlrange="-37 37" />
    <motor gear="1" joint="zarm_l4_joint" name="zarm_l4_joint_motor" ctrllimited="true" ctrlrange="-37 37" />
    <motor gear="1" joint="zarm_r1_joint" name="zarm_r1_joint_motor" ctrllimited="true" ctrlrange="-14.1 14.1" />
    <motor gear="1" joint="zarm_r2_joint" name="zarm_r2_joint_motor" ctrllimited="true" ctrlrange="-37 37" />
    <motor gear="1" joint="zarm_r3_joint" name="zarm_r3_joint_motor" ctrllimited="true" ctrlrange="-37 37" />
    <motor gear="1" joint="zarm_r4_joint" name="zarm_r4_joint_motor" ctrllimited="true" ctrlrange="-37 37" />
    <motor gear="1" joint="zhead_1_joint" name="zhead_1_joint_motor" ctrllimited="true" ctrlrange="-14.1 14.1" />
    <motor gear="1" joint="zhead_2_joint" name="zhead_2_joint_motor" ctrllimited="true" ctrlrange="-14.1 14.1" />
  </actuator>
  <sensor>
    <accelerometer name="BodyAcc" site="imu" />
    <velocimeter name="BodyVel" site="imu" />
    <gyro name="BodyGyro" site="imu" />
    <framepos name="BodyPos" objtype="site" objname="imu" />
    <framequat name="BodyQuat" objtype="site" objname="imu" />
    <jointpos name="leg_l1_joint_pos" joint="leg_l1_joint" />
    <jointpos name="leg_l2_joint_pos" joint="leg_l2_joint" />
    <jointpos name="leg_l3_joint_pos" joint="leg_l3_joint" />
    <jointpos name="leg_l4_joint_pos" joint="leg_l4_joint" />
    <jointpos name="leg_l5_joint_pos" joint="leg_l5_joint" />
    <jointpos name="leg_l6_joint_pos" joint="leg_l6_joint" />
    <jointpos name="leg_r1_joint_pos" joint="leg_r1_joint" />
    <jointpos name="leg_r2_joint_pos" joint="leg_r2_joint" />
    <jointpos name="leg_r3_joint_pos" joint="leg_r3_joint" />
    <jointpos name="leg_r4_joint_pos" joint="leg_r4_joint" />
    <jointpos name="leg_r5_joint_pos" joint="leg_r5_joint" />
    <jointpos name="leg_r6_joint_pos" joint="leg_r6_joint" />
    <jointpos name="waist_yaw_joint_pos" joint="waist_yaw_joint" />
    <jointpos name="zarm_l1_joint_pos" joint="zarm_l1_joint" />
    <jointpos name="zarm_l2_joint_pos" joint="zarm_l2_joint" />
    <jointpos name="zarm_l3_joint_pos" joint="zarm_l3_joint" />
    <jointpos name="zarm_l4_joint_pos" joint="zarm_l4_joint" />
    <jointpos name="zarm_r1_joint_pos" joint="zarm_r1_joint" />
    <jointpos name="zarm_r2_joint_pos" joint="zarm_r2_joint" />
    <jointpos name="zarm_r3_joint_pos" joint="zarm_r3_joint" />
    <jointpos name="zarm_r4_joint_pos" joint="zarm_r4_joint" />
    <jointpos name="zhead_1_joint_pos" joint="zhead_1_joint" />
    <jointpos name="zhead_2_joint_pos" joint="zhead_2_joint" />
    <jointvel name="leg_l1_joint_vel" joint="leg_l1_joint" />
    <jointvel name="leg_l2_joint_vel" joint="leg_l2_joint" />
    <jointvel name="leg_l3_joint_vel" joint="leg_l3_joint" />
    <jointvel name="leg_l4_joint_vel" joint="leg_l4_joint" />
    <jointvel name="leg_l5_joint_vel" joint="leg_l5_joint" />
    <jointvel name="leg_l6_joint_vel" joint="leg_l6_joint" />
    <jointvel name="leg_r1_joint_vel" joint="leg_r1_joint" />
    <jointvel name="leg_r2_joint_vel" joint="leg_r2_joint" />
    <jointvel name="leg_r3_joint_vel" joint="leg_r3_joint" />
    <jointvel name="leg_r4_joint_vel" joint="leg_r4_joint" />
    <jointvel name="leg_r5_joint_vel" joint="leg_r5_joint" />
    <jointvel name="leg_r6_joint_vel" joint="leg_r6_joint" />
    <jointvel name="waist_yaw_joint_vel" joint="waist_yaw_joint" />
    <jointvel name="zarm_l1_joint_vel" joint="zarm_l1_joint" />
    <jointvel name="zarm_l2_joint_vel" joint="zarm_l2_joint" />
    <jointvel name="zarm_l3_joint_vel" joint="zarm_l3_joint" />
    <jointvel name="zarm_l4_joint_vel" joint="zarm_l4_joint" />
    <jointvel name="zarm_r1_joint_vel" joint="zarm_r1_joint" />
    <jointvel name="zarm_r2_joint_vel" joint="zarm_r2_joint" />
    <jointvel name="zarm_r3_joint_vel" joint="zarm_r3_joint" />
    <jointvel name="zarm_r4_joint_vel" joint="zarm_r4_joint" />
    <jointvel name="zhead_1_joint_vel" joint="zhead_1_joint" />
    <jointvel name="zhead_2_joint_vel" joint="zhead_2_joint" />
  </sensor>
</mujoco>
